Traceback (most recent call last):
  File "/Users/madsbertelsen/opt/anaconda3/lib/python3.8/site-packages/jupyter_cache/executors/utils.py", line 51, in single_nb_execution
    executenb(
  File "/Users/madsbertelsen/opt/anaconda3/lib/python3.8/site-packages/nbclient/client.py", line 1112, in execute
    return NotebookClient(nb=nb, resources=resources, km=km, **kwargs).execute()
  File "/Users/madsbertelsen/opt/anaconda3/lib/python3.8/site-packages/nbclient/util.py", line 74, in wrapped
    return just_run(coro(*args, **kwargs))
  File "/Users/madsbertelsen/opt/anaconda3/lib/python3.8/site-packages/nbclient/util.py", line 53, in just_run
    return loop.run_until_complete(coro)
  File "/Users/madsbertelsen/opt/anaconda3/lib/python3.8/asyncio/base_events.py", line 616, in run_until_complete
    return future.result()
  File "/Users/madsbertelsen/opt/anaconda3/lib/python3.8/site-packages/nbclient/client.py", line 553, in async_execute
    await self.async_execute_cell(
  File "/Users/madsbertelsen/opt/anaconda3/lib/python3.8/site-packages/nbclient/client.py", line 857, in async_execute_cell
    self._check_raise_for_error(cell, exec_reply)
  File "/Users/madsbertelsen/opt/anaconda3/lib/python3.8/site-packages/nbclient/client.py", line 760, in _check_raise_for_error
    raise CellExecutionError.from_cell_and_msg(cell, exec_reply_content)
nbclient.exceptions.CellExecutionError: An error occurred while executing the following cell:
------------------
int_par.add_option(1, options_are_legal=True)
int_par.add_option(2, options_are_legal=True)
int_par.add_option(3, options_are_legal=True)

try:
    int_par.value = 10
except:
    print("Failed to set value!")
    
print(int_par)
------------------

[0;31m---------------------------------------------------------------------------[0m
[0;31mValueError[0m                                Traceback (most recent call last)
[0;32m<ipython-input-10-930ecd08c657>[0m in [0;36m<module>[0;34m[0m
[0;32m----> 1[0;31m [0mint_par[0m[0;34m.[0m[0madd_option[0m[0;34m([0m[0;36m1[0m[0;34m,[0m [0moptions_are_legal[0m[0;34m=[0m[0;32mTrue[0m[0;34m)[0m[0;34m[0m[0;34m[0m[0m
[0m[1;32m      2[0m [0mint_par[0m[0;34m.[0m[0madd_option[0m[0;34m([0m[0;36m2[0m[0;34m,[0m [0moptions_are_legal[0m[0;34m=[0m[0;32mTrue[0m[0;34m)[0m[0;34m[0m[0;34m[0m[0m
[1;32m      3[0m [0mint_par[0m[0;34m.[0m[0madd_option[0m[0;34m([0m[0;36m3[0m[0;34m,[0m [0moptions_are_legal[0m[0;34m=[0m[0;32mTrue[0m[0;34m)[0m[0;34m[0m[0;34m[0m[0m
[1;32m      4[0m [0;34m[0m[0m
[1;32m      5[0m [0;32mtry[0m[0;34m:[0m[0;34m[0m[0;34m[0m[0m

[0;32m~/PaNOSC/libpyvinyl/github/libpyvinyl/libpyvinyl/Parameters/Parameter.py[0m in [0;36madd_option[0;34m(self, option, options_are_legal)[0m
[1;32m    334[0m         [0;32mif[0m [0;32mnot[0m [0mself[0m[0;34m.[0m[0mvalue_no_conversion[0m [0;32mis[0m [0;32mNone[0m[0;34m:[0m[0;34m[0m[0;34m[0m[0m
[1;32m    335[0m             [0;32mif[0m [0mself[0m[0;34m.[0m[0mis_legal[0m[0;34m([0m[0mself[0m[0;34m.[0m[0mvalue[0m[0;34m)[0m [0;32mis[0m [0;32mFalse[0m[0;34m:[0m[0;34m[0m[0;34m[0m[0m
[0;32m--> 336[0;31m                 raise ValueError(
[0m[1;32m    337[0m                     [0;34m"Value "[0m[0;34m[0m[0;34m[0m[0m
[1;32m    338[0m                     [0;34m+[0m [0mstr[0m[0;34m([0m[0mself[0m[0;34m.[0m[0mvalue[0m[0;34m)[0m[0;34m[0m[0;34m[0m[0m

[0;31mValueError[0m: Value 3 is now illegal based on the newly added option
ValueError: Value 3 is now illegal based on the newly added option

