Traceback (most recent call last):
  File "/Users/madsbertelsen/opt/anaconda3/lib/python3.8/site-packages/jupyter_cache/executors/utils.py", line 51, in single_nb_execution
    executenb(
  File "/Users/madsbertelsen/opt/anaconda3/lib/python3.8/site-packages/nbclient/client.py", line 1112, in execute
    return NotebookClient(nb=nb, resources=resources, km=km, **kwargs).execute()
  File "/Users/madsbertelsen/opt/anaconda3/lib/python3.8/site-packages/nbclient/util.py", line 74, in wrapped
    return just_run(coro(*args, **kwargs))
  File "/Users/madsbertelsen/opt/anaconda3/lib/python3.8/site-packages/nbclient/util.py", line 53, in just_run
    return loop.run_until_complete(coro)
  File "/Users/madsbertelsen/opt/anaconda3/lib/python3.8/asyncio/base_events.py", line 616, in run_until_complete
    return future.result()
  File "/Users/madsbertelsen/opt/anaconda3/lib/python3.8/site-packages/nbclient/client.py", line 553, in async_execute
    await self.async_execute_cell(
  File "/Users/madsbertelsen/opt/anaconda3/lib/python3.8/site-packages/nbclient/client.py", line 857, in async_execute_cell
    self._check_raise_for_error(cell, exec_reply)
  File "/Users/madsbertelsen/opt/anaconda3/lib/python3.8/site-packages/nbclient/client.py", line 760, in _check_raise_for_error
    raise CellExecutionError.from_cell_and_msg(cell, exec_reply_content)
nbclient.exceptions.CellExecutionError: An error occurred while executing the following cell:
------------------
banana_empty = functions.name_search("banana", data_empty)
banana_wrong = functions.name_search("banana", data_wrong)
banana_sample = functions.name_search("banana", data)

import matplotlib.pyplot as plt
plt.figure(figsize=(14,6))
plt.plot(banana_empty.xaxis, banana_empty.Intensity, "r",
         banana_wrong.xaxis, banana_wrong.Intensity, "b",
         banana_sample.xaxis, banana_sample.Intensity, "k")
plt.xlabel("2Theta [deg]")
plt.ylabel("Intensity [n/s]")
plt.legend(["No sample", "Wrong simulation, no exit", "Full simulation"])
------------------

[0;31m---------------------------------------------------------------------------[0m
[0;31mNameError[0m                                 Traceback (most recent call last)
[0;32m<ipython-input-15-0f093650d9e9>[0m in [0;36m<module>[0;34m[0m
[0;32m----> 1[0;31m [0mbanana_empty[0m [0;34m=[0m [0mfunctions[0m[0;34m.[0m[0mname_search[0m[0;34m([0m[0;34m"banana"[0m[0;34m,[0m [0mdata_empty[0m[0;34m)[0m[0;34m[0m[0;34m[0m[0m
[0m[1;32m      2[0m [0mbanana_wrong[0m [0;34m=[0m [0mfunctions[0m[0;34m.[0m[0mname_search[0m[0;34m([0m[0;34m"banana"[0m[0;34m,[0m [0mdata_wrong[0m[0;34m)[0m[0;34m[0m[0;34m[0m[0m
[1;32m      3[0m [0mbanana_sample[0m [0;34m=[0m [0mfunctions[0m[0;34m.[0m[0mname_search[0m[0;34m([0m[0;34m"banana"[0m[0;34m,[0m [0mdata[0m[0;34m)[0m[0;34m[0m[0;34m[0m[0m
[1;32m      4[0m [0;34m[0m[0m
[1;32m      5[0m [0;32mimport[0m [0mmatplotlib[0m[0;34m.[0m[0mpyplot[0m [0;32mas[0m [0mplt[0m[0;34m[0m[0;34m[0m[0m

[0;31mNameError[0m: name 'functions' is not defined
NameError: name 'functions' is not defined

