Traceback (most recent call last):
  File "/Users/madsbertelsen/opt/anaconda3/lib/python3.8/site-packages/jupyter_cache/executors/utils.py", line 51, in single_nb_execution
    executenb(
  File "/Users/madsbertelsen/opt/anaconda3/lib/python3.8/site-packages/nbclient/client.py", line 1112, in execute
    return NotebookClient(nb=nb, resources=resources, km=km, **kwargs).execute()
  File "/Users/madsbertelsen/opt/anaconda3/lib/python3.8/site-packages/nbclient/util.py", line 74, in wrapped
    return just_run(coro(*args, **kwargs))
  File "/Users/madsbertelsen/opt/anaconda3/lib/python3.8/site-packages/nbclient/util.py", line 53, in just_run
    return loop.run_until_complete(coro)
  File "/Users/madsbertelsen/opt/anaconda3/lib/python3.8/asyncio/base_events.py", line 616, in run_until_complete
    return future.result()
  File "/Users/madsbertelsen/opt/anaconda3/lib/python3.8/site-packages/nbclient/client.py", line 553, in async_execute
    await self.async_execute_cell(
  File "/Users/madsbertelsen/opt/anaconda3/lib/python3.8/site-packages/nbclient/client.py", line 857, in async_execute_cell
    self._check_raise_for_error(cell, exec_reply)
  File "/Users/madsbertelsen/opt/anaconda3/lib/python3.8/site-packages/nbclient/client.py", line 760, in _check_raise_for_error
    raise CellExecutionError.from_cell_and_msg(cell, exec_reply_content)
nbclient.exceptions.CellExecutionError: An error occurred while executing the following cell:
------------------
plotter.make_sub_plot(data)
------------------

[0;31m---------------------------------------------------------------------------[0m
[0;31mAttributeError[0m                            Traceback (most recent call last)
[0;32m<ipython-input-5-e276f97f9245>[0m in [0;36m<module>[0;34m[0m
[0;32m----> 1[0;31m [0mplotter[0m[0;34m.[0m[0mmake_sub_plot[0m[0;34m([0m[0mdata[0m[0;34m)[0m[0;34m[0m[0;34m[0m[0m
[0m
[0;32m~/PaNOSC/McStasScript/github/McStasScript/mcstasscript/interface/plotter.py[0m in [0;36mmake_sub_plot[0;34m(data_list, **kwargs)[0m
[1;32m     58[0m [0;34m[0m[0m
[1;32m     59[0m     [0;32mfor[0m [0mdata[0m[0;34m,[0m [0max0[0m [0;32min[0m [0mzip[0m[0;34m([0m[0mdata_list[0m[0;34m,[0m [0max[0m[0;34m)[0m[0;34m:[0m[0;34m[0m[0;34m[0m[0m
[0;32m---> 60[0;31m         [0m_plot_fig_ax[0m[0;34m([0m[0mdata[0m[0;34m,[0m [0mfig[0m[0;34m,[0m [0max0[0m[0;34m,[0m [0;34m**[0m[0mkwargs[0m[0;34m)[0m[0;34m[0m[0;34m[0m[0m
[0m[1;32m     61[0m [0;34m[0m[0m
[1;32m     62[0m     [0mfig[0m[0;34m.[0m[0mtight_layout[0m[0;34m([0m[0;34m)[0m[0;34m[0m[0;34m[0m[0m

[0;32m~/PaNOSC/McStasScript/github/McStasScript/mcstasscript/helper/plot_helper.py[0m in [0;36m_plot_fig_ax[0;34m(data, fig, ax, **kwargs)[0m
[1;32m     83[0m     """
[1;32m     84[0m [0;34m[0m[0m
[0;32m---> 85[0;31m     [0mprint[0m[0;34m([0m[0;34m"Plotting data with name "[0m [0;34m+[0m [0mdata[0m[0;34m.[0m[0mmetadata[0m[0;34m.[0m[0mcomponent_name[0m[0;34m)[0m[0;34m[0m[0;34m[0m[0m
[0m[1;32m     86[0m     [0;32mif[0m [0mtype[0m[0;34m([0m[0mdata[0m[0;34m.[0m[0mmetadata[0m[0;34m.[0m[0mdimension[0m[0;34m)[0m [0;34m==[0m [0mint[0m[0;34m:[0m[0;34m[0m[0;34m[0m[0m
[1;32m     87[0m [0;34m[0m[0m

[0;31mAttributeError[0m: 'NoneType' object has no attribute 'metadata'
AttributeError: 'NoneType' object has no attribute 'metadata'

