Traceback (most recent call last):
  File "/Users/madsbertelsen/opt/anaconda3/lib/python3.8/site-packages/jupyter_cache/executors/utils.py", line 51, in single_nb_execution
    executenb(
  File "/Users/madsbertelsen/opt/anaconda3/lib/python3.8/site-packages/nbclient/client.py", line 1112, in execute
    return NotebookClient(nb=nb, resources=resources, km=km, **kwargs).execute()
  File "/Users/madsbertelsen/opt/anaconda3/lib/python3.8/site-packages/nbclient/util.py", line 74, in wrapped
    return just_run(coro(*args, **kwargs))
  File "/Users/madsbertelsen/opt/anaconda3/lib/python3.8/site-packages/nbclient/util.py", line 53, in just_run
    return loop.run_until_complete(coro)
  File "/Users/madsbertelsen/opt/anaconda3/lib/python3.8/asyncio/base_events.py", line 616, in run_until_complete
    return future.result()
  File "/Users/madsbertelsen/opt/anaconda3/lib/python3.8/site-packages/nbclient/client.py", line 553, in async_execute
    await self.async_execute_cell(
  File "/Users/madsbertelsen/opt/anaconda3/lib/python3.8/site-packages/nbclient/client.py", line 857, in async_execute_cell
    self._check_raise_for_error(cell, exec_reply)
  File "/Users/madsbertelsen/opt/anaconda3/lib/python3.8/site-packages/nbclient/client.py", line 760, in _check_raise_for_error
    raise CellExecutionError.from_cell_and_msg(cell, exec_reply_content)
nbclient.exceptions.CellExecutionError: An error occurred while executing the following cell:
------------------
banana_can = functions.name_search("banana", data)
banana_cryo = functions.name_search("banana", data_cryo)

import copy
import numpy as np
banana_diff = copy.deepcopy(banana_cryo)
banana_diff.Intensity = banana_cryo.Intensity - banana_can.Intensity
banana_diff.Error = np.sqrt(banana_cryo.Error**2 + banana_can.Error**2)

import matplotlib.pyplot as plt
plt.figure(figsize=(14,6))
plt.plot(banana_can.xaxis, banana_can.Intensity, "r",
         banana_cryo.xaxis, banana_cryo.Intensity, "b",
         banana_diff.xaxis, banana_diff.Intensity-10.0, "k")
plt.xlabel("2Theta [deg]")
plt.ylabel("Intensity [n/s]")
l = plt.legend(["Sample in can", "Sample in can in cryostat", "Difference displaced to -10"])
------------------

[0;31m---------------------------------------------------------------------------[0m
[0;31mNameError[0m                                 Traceback (most recent call last)
[0;32m<ipython-input-17-224151116845>[0m in [0;36m<module>[0;34m[0m
[0;32m----> 1[0;31m [0mbanana_can[0m [0;34m=[0m [0mfunctions[0m[0;34m.[0m[0mname_search[0m[0;34m([0m[0;34m"banana"[0m[0;34m,[0m [0mdata[0m[0;34m)[0m[0;34m[0m[0;34m[0m[0m
[0m[1;32m      2[0m [0mbanana_cryo[0m [0;34m=[0m [0mfunctions[0m[0;34m.[0m[0mname_search[0m[0;34m([0m[0;34m"banana"[0m[0;34m,[0m [0mdata_cryo[0m[0;34m)[0m[0;34m[0m[0;34m[0m[0m
[1;32m      3[0m [0;34m[0m[0m
[1;32m      4[0m [0;32mimport[0m [0mcopy[0m[0;34m[0m[0;34m[0m[0m
[1;32m      5[0m [0;32mimport[0m [0mnumpy[0m [0;32mas[0m [0mnp[0m[0;34m[0m[0;34m[0m[0m

[0;31mNameError[0m: name 'functions' is not defined
NameError: name 'functions' is not defined

